Workbook

Sheet Información completa
B2: CLÁSICA FORK (tiempos en microsegundos)
C4: MATRIZ 600 X 600 | E4: 1 hilo | F4: 2 hilos | G4: 4 hilos | H4: 8 hilos | I4: 12 hilos | J4: 32 hilos | K4: MATRIZ 1200 x 1200 | M4: 1 hilo | N4: 2 hilos | O4: 4 hilos | P4: 8 hilos | Q4: 12 hilos | R4: 32 hilos | S4: MATRIZ 2400 x 2400 | U4: 1 hilo | V4: 2 hilos | W4: 4 hilos | X4: 8 hilos | Y4: 12 hilos | Z4: 32 hilos | AA4: MATRIZ 4800 x 4800 | AC4: 1 hilo | AD4: 2 hilos | AE4: 4 hilos | AF4: 8 hilos | AG4: 12 hilos | AH4: 32 hilos
D5: Repetición #1 | E5: 485558 | F5: 225214 | G5: 175222 | H5: 152628 | I5: 116826 | J5: 109915 | M5: 2862463 | N5: 1413163 | O5: 761203 | P5: 529649 | Q5: 403868 | R5: 257763 | U5: 38688612 | V5: 18134491 | W5: 8750700 | X5: 5202393 | Y5: 5502939 | Z5: 3839319 | AC5: 570504875 | AD5: 185874891 | AE5: 98201964 | AF5: 57802188 | AG5: 62347548 | AH5: 41377876
D6: Repetición #2 | E6: 446813 | F6: 231036 | G6: 158038 | H6: 137826 | I6: 117343 | J6: 107806 | M6: 2840315 | N6: 1379194 | O6: 793846 | P6: 547548 | Q6: 421499 | R6: 283072 | U6: 31593875 | V6: 16828719 | W6: 8921241 | X6: 5278047 | Y6: 5588988 | Z6: 3763119 | AC6: 561367182 | AD6: 189638235 | AE6: 97728646 | AF6: 57067751 | AG6: 62155260 | AH6: 42933862
D7: Repetición #3 | E7: 336275 | F7: 230136 | G7: 155050 | H7: 119886 | I7: 98800 | J7: 106201 | M7: 2739341 | N7: 1463585 | O7: 947571 | P7: 553054 | Q7: 454208 | R7: 307493 | U7: 38151305 | V7: 17305729 | W7: 9184856 | X7: 5283110 | Y7: 5668765 | Z7: 3743008 | AC7: 625076401 | AD7: 190132886 | AE7: 97738521 | AF7: 57886080 | AG7: 61468343 | AH7: 43438258
D8: Repetición #4 | E8: 337186 | F8: 206684 | G8: 190182 | H8: 162382 | I8: 99526 | J8: 116117 | M8: 2780478 | N8: 1406761 | O8: 820370 | P8: 560338 | Q8: 440652 | R8: 263184 | U8: 33085941 | V8: 17294050 | W8: 8969601 | X8: 5508341 | Y8: 5738292 | Z8: 3707176 | AC8: 629212156 | AD8: 189400543 | AE8: 99699746 | AF8: 58287155 | AG8: 62474321 | AH8: 43520104
D9: Repetición #5 | E9: 452266 | F9: 225145 | G9: 160465 | H9: 96186 | I9: 118847 | J9: 107094 | M9: 2774776 | N9: 1380530 | O9: 793516 | P9: 540752 | Q9: 423370 | R9: 256532 | U9: 34313091 | V9: 17645416 | W9: 8846671 | X9: 5615949 | Y9: 5812800 | Z9: 3774755 | AC9: 676282753 | AD9: 190531636 | AE9: 99169045 | AF9: 57963553 | AG9: 62643347 | AH9: 43290210
D10: Repetición #6 | E10: 415994 | F10: 179436 | G10: 176047 | H10: 125317 | I10: 119698 | J10: 111724 | M10: 2760666 | N10: 1403803 | O10: 808308 | P10: 609758 | Q10: 435743 | R10: 294589 | U10: 31914093 | V10: 17395711 | W10: 9224517 | X10: 5268302 | Y10: 5645986 | Z10: 3866560 | AC10: 679660114 | AD10: 189255720 | AE10: 97230584 | AF10: 57400571 | AG10: 62190530 | AH10: 41951551
D11: Repetición #7 | E11: 407903 | F11: 231857 | G11: 153035 | H11: 118519 | I11: 118475 | J11: 114339 | M11: 2826202 | N11: 1387326 | O11: 865700 | P11: 514607 | Q11: 406864 | R11: 247666 | U11: 32677351 | V11: 17861743 | W11: 9141165 | X11: 5282159 | Y11: 5574928 | Z11: 3724796 | AC11: 675987420 | AD11: 189723452 | AE11: 97214012 | AF11: 57987299 | AG11: 62145797 | AH11: 42846269
D12: Repetición #8 | E12: 324401 | F12: 168614 | G12: 158159 | H12: 137594 | I12: 104087 | J12: 85573 | M12: 2820638 | N12: 1411068 | O12: 777247 | P12: 528412 | Q12: 445493 | R12: 303639 | U12: 34859500 | V12: 17813659 | W12: 9213258 | X12: 5299840 | Y12: 5496962 | Z12: 3763957 | AC12: 676455948 | AD12: 188572978 | AE12: 97586954 | AF12: 57205654 | AG12: 61770021 | AH12: 43016467
D13: Repetición #9 | E13: 402811 | F13: 202369 | G13: 183927 | H13: 150301 | I13: 97926 | J13: 111349 | M13: 2765596 | N13: 1450005 | O13: 942738 | P13: 483914 | Q13: 444809 | R13: 330960 | U13: 33401288 | V13: 17683110 | W13: 8940587 | X13: 5656400 | Y13: 5613161 | Z13: 3710881 | AC13: 653728241 | AD13: 189545878 | AE13: 99173524 | AF13: 57962819 | AG13: 60983969 | AH13: 42820957
D14: Repetición #10 | E14: 397607 | F14: 173812 | G14: 135453 | H14: 172010 | I14: 117208 | J14: 113844 | M14: 2822478 | N14: 1422246 | O14: 802404 | P14: 520730 | Q14: 479511 | R14: 279156 | U14: 34558187 | V14: 17494233 | W14: 9431651 | X14: 5268944 | Y14: 5660778 | Z14: 3776926 | AC14: 530761886 | AD14: 188442543 | AE14: 96898056 | AF14: 57275588 | AG14: 62584077 | AH14: 43197133
D15: Repetición #11 | E15: 409919 | F15: 273393 | G15: 166050 | H15: 156630 | I15: 97960 | J15: 114662 | M15: 2735088 | N15: 1381640 | O15: 756368 | P15: 526718 | Q15: 427726 | R15: 272828 | U15: 33677564 | V15: 17550596 | W15: 9100304 | X15: 5335665 | Y15: 5634698 | Z15: 3806781 | AC15: 438166925 | AD15: 185850673 | AE15: 98915915 | AF15: 57937451 | AG15: 62184790 | AH15: 42912483
D16: Repetición #12 | E16: 409758 | F16: 231682 | G16: 164564 | H16: 171347 | I16: 88902 | J16: 109034 | M16: 2883903 | N16: 1505873 | O16: 810295 | P16: 503040 | Q16: 431292 | R16: 342861 | U16: 33128640 | V16: 17360001 | W16: 8884132 | X16: 5309989 | Y16: 5575758 | Z16: 3687382 | AC16: 646229523 | AD16: 189056932 | AE16: 98937582 | AF16: 58104845 | AG16: 62142820 | AH16: 42833676
... D34: Repetición #30 | E34: 381660 | F34: 219435 | G34: 204393 | H34: 151178 | I34: 118601 | J34: 112077 | M34: 2859911 | N34: 1392281 | O34: 932962 | P34: 556676 | Q34: 456600 | R34: 262435 | U34: 32699163 | V34: 16895488 | W34: 9081301 | X34: 5348747 | Y34: 5525841 | Z34: 3780503 | AC34: 269466122 | AD34: 185395826 | AE34: 98465325 | AF34: 57521995 | AG34: 62391375 | AH34: 42865703
D35: PROMEDIO | E35: {=ROUND(AVERAGE(IF((ISNUMBER(E5:E34))*(E5:E34<LARGE(E5:E34,2))*(E5:E34>SMALL(E5:E34,2)),E5:E34)),0)} -> 395790 | F35: {=ROUND(AVERAGE(IF((ISNUMBER(F5:F34))*(F5:F34<LARGE(F5:F34,2))*(F5:F34>SMALL(F5:F34,2)),F5:F34)),0)} -> 221549 | G35: {=ROUND(AVERAGE(IF((ISNUMBER(G5:G34))*(G5:G34<LARGE(G5:G34,2))*(G5:G34>SMALL(G5:G34,2)),G5:G34)),0)} -> 161865 | H35: {=ROUND(AVERAGE(IF((ISNUMBER(H5:H34))*(H5:H34<LARGE(H5:H34,2))*(H5:H34>SMALL(H5:H34,2)),H5:H34)),0)} -> 144469 | I35: {=ROUND(AVERAGE(IF((ISNUMBER(I5:I34))*(I5:I34<LARGE(I5:I34,2))*(I5:I34>SMALL(I5:I34,2)),I5:I34)),0)} -> 109948 | J35: {=ROUND(AVERAGE(IF((ISNUMBER(J5:J34))*(J5:J34<LARGE(J5:J34,2))*(J5:J34>SMALL(J5:J34,2)),J5:J34)),0)} -> 109489 | M35: {=ROUND(AVERAGE(IF((ISNUMBER(M5:M34))*(M5:M34<LARGE(M5:M34,2))*(M5:M34>SMALL(M5:M34,2)),M5:M34)),0)} -> 2797186 | N35: {=ROUND(AVERAGE(IF((ISNUMBER(N5:N34))*(N5:N34<LARGE(N5:N34,2))*(N5:N34>SMALL(N5:N34,2)),N5:N34)),0)} -> 1417962 | O35: {=ROUND(AVERAGE(IF((ISNUMBER(O5:O34))*(O5:O34<LARGE(O5:O34,2))*(O5:O34>SMALL(O5:O34,2)),O5:O34)),0)} -> 831491 | P35: {=ROUND(AVERAGE(IF((ISNUMBER(P5:P34))*(P5:P34<LARGE(P5:P34,2))*(P5:P34>SMALL(P5:P34,2)),P5:P34)),0)} -> 539708 | Q35: {=ROUND(AVERAGE(IF((ISNUMBER(Q5:Q34))*(Q5:Q34<LARGE(Q5:Q34,2))*(Q5:Q34>SMALL(Q5:Q34,2)),Q5:Q34)),0)} -> 439426 | R35: {=ROUND(AVERAGE(IF((ISNUMBER(R5:R34))*(R5:R34<LARGE(R5:R34,2))*(R5:R34>SMALL(R5:R34,2)),R5:R34)),0)} -> 274450 | U35: {=ROUND(AVERAGE(IF((ISNUMBER(U5:U34))*(U5:U34<LARGE(U5:U34,2))*(U5:U34>SMALL(U5:U34,2)),U5:U34)),0)} -> 33274558 | V35: {=ROUND(AVERAGE(IF((ISNUMBER(V5:V34))*(V5:V34<LARGE(V5:V34,2))*(V5:V34>SMALL(V5:V34,2)),V5:V34)),0)} -> 17466949 | W35: {=ROUND(AVERAGE(IF((ISNUMBER(W5:W34))*(W5:W34<LARGE(W5:W34,2))*(W5:W34>SMALL(W5:W34,2)),W5:W34)),0)} -> 9105632 | X35: {=ROUND(AVERAGE(IF((ISNUMBER(X5:X34))*(X5:X34<LARGE(X5:X34,2))*(X5:X34>SMALL(X5:X34,2)),X5:X34)),0)} -> 5368779 | Y35: {=ROUND(AVERAGE(IF((ISNUMBER(Y5:Y34))*(Y5:Y34<LARGE(Y5:Y34,2))*(Y5:Y34>SMALL(Y5:Y34,2)),Y5:Y34)),0)} -> 5642010 | Z35: {=ROUND(AVERAGE(IF((ISNUMBER(Z5:Z34))*(Z5:Z34<LARGE(Z5:Z34,2))*(Z5:Z34>SMALL(Z5:Z34,2)),Z5:Z34)),0)} -> 3779028 | AC35: {=ROUND(AVERAGE(IF((ISNUMBER(AC5:AC34))*(AC5:AC34<LARGE(AC5:AC34,2))*(AC5:AC34>SMALL(AC5:AC34,2)),AC5:AC34)),0)} -> 534112516 | AD35: {=ROUND(AVERAGE(IF((ISNUMBER(AD5:AD34))*(AD5:AD34<LARGE(AD5:AD34,2))*(AD5:AD34>SMALL(AD5:AD34,2)),AD5:AD34)),0)} -> 188752044 | AE35: {=ROUND(AVERAGE(IF((ISNUMBER(AE5:AE34))*(AE5:AE34<LARGE(AE5:AE34,2))*(AE5:AE34>SMALL(AE5:AE34,2)),AE5:AE34)),0)} -> 97791893 | AF35: {=ROUND(AVERAGE(IF((ISNUMBER(AF5:AF34))*(AF5:AF34<LARGE(AF5:AF34,2))*(AF5:AF34>SMALL(AF5:AF34,2)),AF5:AF34)),0)} -> 57692937 | AG35: {=ROUND(AVERAGE(IF((ISNUMBER(AG5:AG34))*(AG5:AG34<LARGE(AG5:AG34,2))*(AG5:AG34>SMALL(AG5:AG34,2)),AG5:AG34)),0)} -> 62382517 | AH35: {=ROUND(AVERAGE(IF((ISNUMBER(AH5:AH34))*(AH5:AH34<LARGE(AH5:AH34,2))*(AH5:AH34>SMALL(AH5:AH34,2)),AH5:AH34)),0)} -> 42968365
B38: CLÁSICA OPENMP (tiempos en microsegundos)
C40: MATRIZ 600 X 600 | E40: 1 hilo | F40: 2 hilos | G40: 4 hilos | H40: 8 hilos | I40: 12 hilos | J40: 32 hilos | K40: MATRIZ 1200 x 1200 | M40: 1 hilo | N40: 2 hilos | O40: 4 hilos | P40: 8 hilos | Q40: 12 hilos | R40: 32 hilos | S40: MATRIZ 2400 x 2400 | U40: 1 hilo | V40: 2 hilos | W40: 4 hilos | X40: 8 hilos | Y40: 12 hilos | Z40: 32 hilos | AA40: MATRIZ 4800 x 4800 | AC40: 1 hilo | AD40: 2 hilos | AE40: 4 hilos | AF40: 8 hilos | AG40: 12 hilos | AH40: 32 hilos
D41: Repetición #1 | E41: 168394 | F41: 64664 | G41: 79856 | H41: 54557 | I41: 50003 | J41: 24935 | M41: 989884 | N41: 538152 | O41: 298097 | P41: 205693 | Q41: 174603 | R41: 208126 | U41: 34715956 | V41: 15548139 | W41: 7436872 | X41: 4505995 | Y41: 4505531 | Z41: 3578237 | AC41: 705568935 | AD41: 203631419 | AE41: 99612627 | AF41: 65908812 | AG41: 62500216 | AH41: 44228859
D42: Repetición #2 | E42: 100769 | F42: 107908 | G42: 82797 | H42: 52951 | I42: 47243 | J42: 23782 | M42: 979762 | N42: 537866 | O42: 278879 | P42: 250890 | Q42: 219250 | R42: 205401 | U42: 27848484 | V42: 16301389 | W42: 7571037 | X42: 4373073 | Y42: 4532568 | Z42: 3610765 | AC42: 754716499 | AD42: 203612276 | AE42: 104603741 | AF42: 66009136 | AG42: 63050097 | AH42: 42219423
D43: Repetición #3 | E43: 173007 | F43: 111697 | G43: 72824 | H43: 52787 | I43: 51649 | J43: 24673 | M43: 1017138 | N43: 579872 | O43: 328489 | P43: 210381 | Q43: 176229 | R43: 198957 | U43: 26749562 | V43: 15569110 | W43: 7698825 | X43: 4407925 | Y43: 4603261 | Z43: 3683604 | AC43: 738241090 | AD43: 204662428 | AE43: 107710229 | AF43: 65762637 | AG43: 62273499 | AH43: 42804394
D44: Repetición #4 | E44: 181877 | F44: 125330 | G44: 52506 | H44: 54725 | I44: 55568 | J44: 23087 | M44: 1006420 | N44: 540150 | O44: 286456 | P44: 215981 | Q44: 168391 | R44: 198996 | U44: 27984684 | V44: 16167071 | W44: 7568359 | X44: 4512845 | Y44: 4592476 | Z44: 3722458 | AC44: 724400379 | AD44: 204012816 | AE44: 102139486 | AF44: 65894444 | AG44: 62445235 | AH44: 44920088
D45: Repetición #5 | E45: 188808 | F45: 106507 | G45: 68798 | H45: 54968 | I45: 49566 | J45: 24573 | M45: 952056 | N45: 546900 | O45: 316422 | P45: 209908 | Q45: 178231 | R45: 152358 | U45: 24952444 | V45: 15635808 | W45: 7399663 | X45: 4534433 | Y45: 4580473 | Z45: 3703103 | AC45: 739139507 | AD45: 203783644 | AE45: 100912546 | AF45: 65814118 | AG45: 63813981 | AH45: 43530507
D46: Repetición #6 | E46: 157330 | F46: 54713 | G46: 70309 | H46: 53671 | I46: 50712 | J46: 24860 | M46: 948822 | N46: 515958 | O46: 299765 | P46: 242216 | Q46: 163987 | R46: 196438 | U46: 26559337 | V46: 15927083 | W46: 7689488 | X46: 4665997 | Y46: 4646115 | Z46: 3798653 | AC46: 734454691 | AD46: 203316199 | AE46: 100646795 | AF46: 66057072 | AG46: 62722554 | AH46: 42686379
D47: Repetición #7 | E47: 173074 | F47: 45537 | G47: 85482 | H47: 56362 | I47: 50872 | J47: 23480 | M47: 1008408 | N47: 537126 | O47: 313941 | P47: 198415 | Q47: 168132 | R47: 204127 | U47: 26807291 | V47: 15511538 | W47: 7636636 | X47: 4641713 | Y47: 4532241 | Z47: 3719040 | AC47: 729100749 | AD47: 204488501 | AE47: 100173468 | AF47: 65671927 | AG47: 62544968 | AH47: 42362119
D48: Repetición #8 | E48: 86245 | F48: 106365 | G48: 81664 | H48: 54695 | I48: 51900 | J48: 27595 | M48: 985504 | N48: 535101 | O48: 304745 | P48: 212670 | Q48: 165250 | R48: 195607 | U48: 26539844 | V48: 15467490 | W48: 7426955 | X48: 4576416 | Y48: 4592689 | Z48: 3733002 | AC48: 717736240 | AD48: 203987818 | AE48: 101184732 | AF48: 65960836 | AG48: 62455319 | AH48: 42464499
D49: Repetición #9 | E49: 86692 | F49: 108967 | G49: 84872 | H49: 55203 | I49: 52727 | J49: 24194 | M49: 1002980 | N49: 536771 | O49: 310912 | P49: 222365 | Q49: 180085 | R49: 230635 | U49: 27405683 | V49: 15569045 | W49: 7370113 | X49: 4560363 | Y49: 4668039 | Z49: 3753104 | AC49: 676609617 | AD49: 201784784 | AE49: 100769449 | AF49: 65967619 | AG49: 62776281 | AH49: 41968657
D50: Repetición #10 | E50: 160360 | F50: 111404 | G50: 72652 | H50: 51977 | I50: 52301 | J50: 24267 | M50: 938811 | N50: 533488 | O50: 325950 | P50: 247790 | Q50: 167033 | R50: 244796 | U50: 26533935 | V50: 15760604 | W50: 7825313 | X50: 4733668 | Y50: 4627420 | Z50: 3786141 | AC50: 734906468 | AD50: 202171772 | AE50: 101207488 | AF50: 65918238 | AG50: 62397226 | AH50: 42421426
D51: Repetición #11 | E51: 164124 | F51: 127422 | G51: 49090 | H51: 52032 | I51: 53227 | J51: 25617 | M51: 945704 | N51: 576480 | O51: 283621 | P51: 217126 | Q51: 172342 | R51: 226399 | U51: 26627468 | V51: 16052983 | W51: 7523012 | X51: 4513348 | Y51: 4636350 | Z51: 3644123 | AC51: 664685710 | AD51: 203498808 | AE51: 100811886 | AF51: 66133228 | AG51: 62380867 | AH51: 42934181
D52: Repetición #12 | E52: 159978 | F52: 126696 | G52: 54698 | H52: 51866 | I52: 53591 | J52: 24743 | M52: 927592 | N52: 516879 | O52: 288986 | P52: 221032 | Q52: 169034 | R52: 212975 | U52: 26131751 | V52: 15438212 | W52: 7411336 | X52: 4490903 | Y52: 4577585 | Z52: 3722798 | AC52: 614823362 | AD52: 202805322 | AE52: 102356862 | AF52: 65763338 | AG52: 62941594 | AH52: 42378920
... D70: Repetición #30 | E70: 172401 | F70: 107655 | G70: 73234 | H70: 54207 | I70: 50585 | J70: 23472 | M70: 1159701 | N70: 552067 | O70: 334881 | P70: 240088 | Q70: 160725 | R70: 203864 | U70: 23983206 | V70: 16035725 | W70: 7622131 | X70: 4452144 | Y70: 4714043 | Z70: 3765919 | AC70: 698101967 | AD70: 203372546 | AE70: 103653484 | AF70: 66103637 | AG70: 62045052 | AH70: 42934711
D71: PROMEDIO | E71: {=ROUND(AVERAGE(IF((ISNUMBER(E41:E70))*(E41:E70<LARGE(E41:E70,2))*(E41:E70>SMALL(E41:E70,2)),E41:E70)),0)} -> 152489 | F71: {=ROUND(AVERAGE(IF((ISNUMBER(F41:F70))*(F41:F70<LARGE(F41:F70,2))*(F41:F70>SMALL(F41:F70,2)),F41:F70)),0)} -> 95962 | G71: {=ROUND(AVERAGE(IF((ISNUMBER(G41:G70))*(G41:G70<LARGE(G41:G70,2))*(G41:G70>SMALL(G41:G70,2)),G41:G70)),0)} -> 74085 | H71: {=ROUND(AVERAGE(IF((ISNUMBER(H41:H70))*(H41:H70<LARGE(H41:H70,2))*(H41:H70>SMALL(H41:H70,2)),H41:H70)),0)} -> 53879 | I71: {=ROUND(AVERAGE(IF((ISNUMBER(I41:I70))*(I41:I70<LARGE(I41:I70,2))*(I41:I70>SMALL(I41:I70,2)),I41:I70)),0)} -> 51998 | J71: {=ROUND(AVERAGE(IF((ISNUMBER(J41:J70))*(J41:J70<LARGE(J41:J70,2))*(J41:J70>SMALL(J41:J70,2)),J41:J70)),0)} -> 24656 | M71: {=ROUND(AVERAGE(IF((ISNUMBER(M41:M70))*(M41:M70<LARGE(M41:M70,2))*(M41:M70>SMALL(M41:M70,2)),M41:M70)),0)} -> 978412 | N71: {=ROUND(AVERAGE(IF((ISNUMBER(N41:N70))*(N41:N70<LARGE(N41:N70,2))*(N41:N70>SMALL(N41:N70,2)),N41:N70)),0)} -> 540877 | O71: {=ROUND(AVERAGE(IF((ISNUMBER(O41:O70))*(O41:O70<LARGE(O41:O70,2))*(O41:O70>SMALL(O41:O70,2)),O41:O70)),0)} -> 304147 | P71: {=ROUND(AVERAGE(IF((ISNUMBER(P41:P70))*(P41:P70<LARGE(P41:P70,2))*(P41:P70>SMALL(P41:P70,2)),P41:P70)),0)} -> 220224 | Q71: {=ROUND(AVERAGE(IF((ISNUMBER(Q41:Q70))*(Q41:Q70<LARGE(Q41:Q70,2))*(Q41:Q70>SMALL(Q41:Q70,2)),Q41:Q70)),0)} -> 176600 | R71: {=ROUND(AVERAGE(IF((ISNUMBER(R41:R70))*(R41:R70<LARGE(R41:R70,2))*(R41:R70>SMALL(R41:R70,2)),R41:R70)),0)} -> 196862 | U71: {=ROUND(AVERAGE(IF((ISNUMBER(U41:U70))*(U41:U70<LARGE(U41:U70,2))*(U41:U70>SMALL(U41:U70,2)),U41:U70)),0)} -> 26592717 | V71: {=ROUND(AVERAGE(IF((ISNUMBER(V41:V70))*(V41:V70<LARGE(V41:V70,2))*(V41:V70>SMALL(V41:V70,2)),V41:V70)),0)} -> 15768801 | W71: {=ROUND(AVERAGE(IF((ISNUMBER(W41:W70))*(W41:W70<LARGE(W41:W70,2))*(W41:W70>SMALL(W41:W70,2)),W41:W70)),0)} -> 7564411 | X71: {=ROUND(AVERAGE(IF((ISNUMBER(X41:X70))*(X41:X70<LARGE(X41:X70,2))*(X41:X70>SMALL(X41:X70,2)),X41:X70)),0)} -> 4521071 | Y71: {=ROUND(AVERAGE(IF((ISNUMBER(Y41:Y70))*(Y41:Y70<LARGE(Y41:Y70,2))*(Y41:Y70>SMALL(Y41:Y70,2)),Y41:Y70)),0)} -> 4612473 | Z71: {=ROUND(AVERAGE(IF((ISNUMBER(Z41:Z70))*(Z41:Z70<LARGE(Z41:Z70,2))*(Z41:Z70>SMALL(Z41:Z70,2)),Z41:Z70)),0)} -> 3729862 | AC71: {=ROUND(AVERAGE(IF((ISNUMBER(AC41:AC70))*(AC41:AC70<LARGE(AC41:AC70,2))*(AC41:AC70>SMALL(AC41:AC70,2)),AC41:AC70)),0)} -> 721473512 | AD71: {=ROUND(AVERAGE(IF((ISNUMBER(AD41:AD70))*(AD41:AD70<LARGE(AD41:AD70,2))*(AD41:AD70>SMALL(AD41:AD70,2)),AD41:AD70)),0)} -> 203236743 | AE71: {=ROUND(AVERAGE(IF((ISNUMBER(AE41:AE70))*(AE41:AE70<LARGE(AE41:AE70,2))*(AE41:AE70>SMALL(AE41:AE70,2)),AE41:AE70)),0)} -> 102562613 | AF71: {=ROUND(AVERAGE(IF((ISNUMBER(AF41:AF70))*(AF41:AF70<LARGE(AF41:AF70,2))*(AF41:AF70>SMALL(AF41:AF70,2)),AF41:AF70)),0)} -> 65972682 | AG71: {=ROUND(AVERAGE(IF((ISNUMBER(AG41:AG70))*(AG41:AG70<LARGE(AG41:AG70,2))*(AG41:AG70>SMALL(AG41:AG70,2)),AG41:AG70)),0)} -> 62808022 | AH71: {=ROUND(AVERAGE(IF((ISNUMBER(AH41:AH70))*(AH41:AH70<LARGE(AH41:AH70,2))*(AH41:AH70>SMALL(AH41:AH70,2)),AH41:AH70)),0)} -> 42752207
B74: CLÁSICA POSIX (tiempos en microsegundos)
C76: MATRIZ 600 X 600 | E76: 1 hilo | F76: 2 hilos | G76: 4 hilos | H76: 8 hilos | I76: 12 hilos | J76: 32 hilos | K76: MATRIZ 1200 x 1200 | M76: 1 hilo | N76: 2 hilos | O76: 4 hilos | P76: 8 hilos | Q76: 12 hilos | R76: 32 hilos | S76: MATRIZ 2400 x 2400 | U76: 1 hilo | V76: 2 hilos | W76: 4 hilos | X76: 8 hilos | Y76: 12 hilos | Z76: 32 hilos | AA76: MATRIZ 4800 x 4800 | AC76: 1 hilo | AD76: 2 hilos | AE76: 4 hilos | AF76: 8 hilos | AG76: 12 hilos | AH76: 32 hilos
D77: Repetición #1 | E77: 474389 | F77: 250260 | G77: 172390 | H77: 147824 | I77: 127679 | J77: 72549 | M77: 2775008 | N77: 1425529 | O77: 741530 | P77: 507167 | Q77: 428888 | R77: 276946 | U77: 38023742 | V77: 16722199 | W77: 9179731 | X77: 5103540 | Y77: 5721512 | Z77: 3451914 | AC77: 677302195 | AD77: 184792237 | AE77: 96415088 | AF77: 56668912 | AG77: 61968374 | AH77: 40573152
D78: Repetición #2 | E78: 450728 | F78: 246080 | G78: 173479 | H78: 151425 | I78: 130238 | J78: 71596 | M78: 2822732 | N78: 1407078 | O78: 762521 | P78: 514889 | Q78: 485402 | R78: 242494 | U78: 40404549 | V78: 17046610 | W78: 9234678 | X78: 5249450 | Y78: 5826403 | Z78: 3671502 | AC78: 267988567 | AD78: 188934647 | AE78: 96200362 | AF78: 57778718 | AG78: 61162931 | AH78: 40678169
D79: Repetición #3 | E79: 402614 | F79: 236414 | G79: 172291 | H79: 163859 | I79: 125903 | J79: 72302 | M79: 2822855 | N79: 1370139 | O79: 812286 | P79: 560155 | Q79: 447202 | R79: 266548 | U79: 35697125 | V79: 16730358 | W79: 9102895 | X79: 5445186 | Y79: 5507392 | Z79: 3788369 | AC79: 585508781 | AD79: 189898701 | AE79: 96212500 | AF79: 56164928 | AG79: 61295711 | AH79: 42850696
D80: Repetición #4 | E80: 432754 | F80: 231427 | G80: 209216 | H80: 108080 | I80: 121917 | J80: 74222 | M80: 2782824 | N80: 1446666 | O80: 877420 | P80: 501113 | Q80: 416901 | R80: 259113 | U80: 31591395 | V80: 16406652 | W80: 9113358 | X80: 5198364 | Y80: 5745516 | Z80: 3740803 | AC80: 621770701 | AD80: 190027409 | AE80: 96292809 | AF80: 57740084 | AG80: 61836587 | AH80: 41421643
D81: Repetición #5 | E81: 388028 | F81: 233853 | G81: 200742 | H81: 148329 | I81: 120582 | J81: 69602 | M81: 2744964 | N81: 1435697 | O81: 890644 | P81: 494516 | Q81: 407615 | R81: 231252 | U81: 31180097 | V81: 16744073 | W81: 8764452 | X81: 5486917 | Y81: 5888338 | Z81: 3677413 | AC81: 437578711 | AD81: 187904363 | AE81: 96529093 | AF81: 57428709 | AG81: 62708430 | AH81: 42085937
D82: Repetición #6 | E82: 406647 | F82: 231150 | G82: 181242 | H82: 153168 | I82: 130699 | J82: 74766 | M82: 2748393 | N82: 1434625 | O82: 770336 | P82: 513334 | Q82: 458793 | R82: 242294 | U82: 30477655 | V82: 17845559 | W82: 8968522 | X82: 5477566 | Y82: 5508125 | Z82: 3725476 | AC82: 647900084 | AD82: 189820970 | AE82: 97185972 | AF82: 57559495 | AG82: 61537542 | AH82: 40757672
...

Sheet Gráficas SpeedUp
C7: CLÁSICA FORK (tiempos en microsegundos)
C8: # Hilos | D8: 1 hilo | E8: 2 hilos | F8: 4 hilos | G8: 8 hilos | H8: 12 hilos | I8: 32 hilos | K8: # Hilos | M8: 1 hilo | N8: 2 hilos | O8: 4 hilos | P8: 8 hilos | Q8: 12 hilos | R8: 32 hilos
C9: SpeedUp Matrices 600 x 600 | D9: 1 | E9: =$D10/E10 -> 1.7864671 | F9: =$D10/F10 -> 2.4451858 | G9: =$D10/G10 -> 2.7396189 | H9: =$D10/H10 -> 3.5997926 | I9: =$D10/I10 -> 3.6148837 | K9: Speed Up Promedio | M9: =(D9+D12+D15+D18)/4 -> 1 | N9: =(E9+E12+E15+E18)/4 -> 2.1234633 | O9: =(F9+F12+F15+F18)/4 -> 3.7313138 | P9: =(G9+G12+G15+G18)/4 -> 5.8445084 | Q9: =(H9+H12+H15+H18)/4 -> 6.1062186 | R9: =(I9+I12+I15+I18)/4 -> 8.7605692
C10: Promedio Matrices 600 x 600 | D10: ='Información completa'!E35 -> 395790 | E10: ='Información completa'!F35 -> 221549 | F10: ='Información completa'!G35 -> 161865 | G10: ='Información completa'!H35 -> 144469 | H10: ='Información completa'!I35 -> 109948 | I10: ='Información completa'!J35 -> 109489
C11: # Hilos | D11: 1 hilo | E11: 2 hilos | F11: 4 hilos | G11: 8 hilos | H11: 12 hilos | I11: 32 hilos
C12: SpeedUp Matrices 1200 x 1200 | D12: 1 | E12: =$D13/E13 -> 1.9726805 | F12: =$D13/F13 -> 3.3640605 | G12: =$D13/G13 -> 5.1827766 | H12: =$D13/H13 -> 6.3655451 | I12: =$D13/I13 -> 10.191969
C13: Promedio Matrices 1200 x 1200 | D13: ='Información completa'!M35 -> 2797186 | E13: ='Información completa'!N35 -> 1417962 | F13: ='Información completa'!O35 -> 831491 | G13: ='Información completa'!P35 -> 539708 | H13: ='Información completa'!Q35 -> 439426 | I13: ='Información completa'!R35 -> 274450
C14: # Hilos | D14: 1 hilo | E14: 2 hilos | F14: 4 hilos | G14: 8 hilos | H14: 12 hilos | I14: 32 hilos
C15: SpeedUp Matrices 2400 x 2400 | D15: 1 | E15: =$D16/E16 -> 1.9050012 | F15: =$D16/F16 -> 3.6542832 | G15: =$D16/G16 -> 6.1977887 | H15: =$D16/H16 -> 5.8976425 | I15: =$D16/I16 -> 8.8050573
C16: Promedio Matrices 2400 x 2400 | D16: ='Información completa'!U35 -> 33274558 | E16: ='Información completa'!V35 -> 17466949 | F16: ='Información completa'!W35 -> 9105632 | G16: ='Información completa'!X35 -> 5368779 | H16: ='Información completa'!Y35 -> 5642010 | I16: ='Información completa'!Z35 -> 3779028
C17: # Hilos | D17: 1 hilo | E17: 2 hilos | F17: 4 hilos | G17: 8 hilos | H17: 12 hilos | I17: 32 hilos
C18: SpeedUp Matrices 4800 x 4800 | D18: 1 | E18: =$D19/E19 -> 2.8297045 | F18: =$D19/F19 -> 5.4617259 | G18: =$D19/G19 -> 9.2578493 | H18: =$D19/H19 -> 8.5618943 | I18: =$D19/I19 -> 12.430366
C19: Promedio Matrices 4800 x 4800 | D19: ='Información completa'!AC35 -> 534112516 | E19: ='Información completa'!AD35 -> 188752044 | F19: ='Información completa'!AE35 -> 97791893 | G19: ='Información completa'!AF35 -> 57692937 | H19: ='Información completa'!AG35 -> 62382517 | I19: ='Información completa'!AH35 -> 42968365
C75: CLÁSICA OPENMP (tiempos en microsegundos)
C76: # Hilos | D76: 1 hilo | E76: 2 hilos | F76: 4 hilos | G76: 8 hilos | H76: 12 hilos | I76: 32 hilos | K76: # Hilos | M76: 1 hilo | N76: 2 hilos | O76: 4 hilos | P76: 8 hilos | Q76: 12 hilos | R76: 32 hilos
C77: SpeedUp Matrices 600 x 600 | D77: 1 | E77: =$D78/E78 -> 1.5890561 | F77: =$D78/F78 -> 2.0582979 | G77: =$D78/G78 -> 2.8302121 | H77: =$D78/H78 -> 2.9325936 | I77: =$D78/I78 -> 6.1846609 | K77: Speed Up Promedio | M77: =(D77+D80+D83+D86)/4 -> 1 | N77: =(E77+E80+E83+E86)/4 -> 2.1585806 | O77: =(F77+F80+F83+F86)/4 -> 3.9562939 | P77: =(G77+G80+G83+G86)/4 -> 6.0227275 | Q77: =(H77+H80+H83+H86)/4 -> 6.4313055 | R77: =(I77+I80+I83+I86)/4 -> 8.7900204
C78: Promedio Matrices 600 x 600 | D78: ='Información completa'!E71 -> 152489 | E78: ='Información completa'!F71 -> 95962 | F78: ='Información completa'!G71 -> 74085 | G78: ='Información completa'!H71 -> 53879 | H78: ='Información completa'!I71 -> 51998 | I78: ='Información completa'!J71 -> 24656
C79: # Hilos | D79: 1 hilo | E79: 2 hilos | F79: 4 hilos | G79: 8 hilos | H79: 12 hilos | I79: 32 hilos
C80: SpeedUp Matrices 1200 x 1200 | D80: 1 | E80: =$D81/E81 -> 1.8089362 | F80: =$D81/F81 -> 3.216905 | G80: =$D81/G81 -> 4.4428037 | H80: =$D81/H81 -> 5.5402718 | I80: =$D81/I81 -> 4.9700399
C81: Promedio Matrices 1200 x 1200 | D81: ='Información completa'!M71 -> 978412 | E81: ='Información completa'!N71 -> 540877 | F81: ='Información completa'!O71 -> 304147 | G81: ='Información completa'!P71 -> 220224 | H81: ='Información completa'!Q71 -> 176600 | I81: ='Información completa'!R71 -> 196862
C82: # Hilos | D82: 1 hilo | E82: 2 hilos | F82: 4 hilos | G82: 8 hilos | H82: 12 hilos | I82: 32 hilos
C83: SpeedUp Matrices 2400 x 2400 | D83: 1 | E83: =$D84/E84 -> 1.6864134 | F83: =$D84/F84 -> 3.515504 | G83: =$D84/G84 -> 5.8819508 | H83: =$D84/H84 -> 5.7653924 | I83: =$D84/I84 -> 7.1296785
C84: Promedio Matrices 2400 x 2400 | D84: ='Información completa'!U71 -> 26592717 | E84: ='Información completa'!V71 -> 15768801 | F84: ='Información completa'!W71 -> 7564411 | G84: ='Información completa'!X71 -> 4521071 | H84: ='Información completa'!Y71 -> 4612473 | I84: ='Información completa'!Z71 -> 3729862
C85: # Hilos | D85: 1 hilo | E85: 2 hilos | F85: 4 hilos | G85: 8 hilos | H85: 12 hilos | I85: 32 hilos
C86: SpeedUp Matrices 4800 x 4800 | D86: 1 | E86: =$D87/E87 -> 3.5499167 | F86: =$D87/F87 -> 7.0344689 | G86: =$D87/G87 -> 10.935943 | H86: =$D87/H87 -> 11.486964 | I86: =$D87/I87 -> 16.875702
C87: Promedio Matrices 4800 x 4800 | D87: ='Información completa'!AC71 -> 721473512 | E87: ='Información completa'!AD71 -> 203236743 | F87: ='Información completa'!AE71 -> 102562613 | G87: ='Información completa'!AF71 -> 65972682 | H87: ='Información completa'!AG71 -> 62808022 | I87: ='Información completa'!AH71 -> 42752207
C143: CLÁSICA POSIX (tiempos en microsegundos)
C144: # Hilos | D144: 1 hilo | E144: 2 hilos | F144: 4 hilos | G144: 8 hilos | H144: 12 hilos | I144: 32 hilos | K144: # Hilos | M144: 1 hilo | N144: 2 hilos | O144: 4 hilos | P144: 8 hilos | Q144: 12 hilos | R144: 32 hilos
C145: SpeedUp Matrices 600 x 600 | D145: 1 | E145: =$D146/E146 -> 1.6412322 | F145: =$D146/F146 -> 2.1959472 | G145: =$D146/G146 -> 2.599285 | H145: =$D146/H146 -> 3.055109 | I145: =$D146/I146 -> 5.4141017 | K145: Speed Up Promedio | M145: =(D145+D148+D151+D154)/4 -> 1 | N145: =(E145+E148+E151+E154)/4 -> 2.0800146 | O145: =(F145+F148+F151+F154)/4 -> 3.6504917 | P145: =(G145+G148+G151+G154)/4 -> 5.8322566 | Q145: =(H145+H148+H151+H154)/4 -> 5.9361241 | R145: =(I145+I148+I151+I154)/4 -> 9.4727322
C146: Promedio Matrices 600 x 600 | D146: ='Información completa'!E107 -> 392609 | E146: ='Información completa'!F107 -> 239216 | F146: ='Información completa'!G107 -> 178788 | G146: ='Información completa'!H107 -> 151045 | H146: ='Información completa'!I107 -> 128509 | I146: ='Información completa'!J107 -> 72516
C147: # Hilos | D147: 1 hilo | E147: 2 hilos | F147: 4 hilos | G147: 8 hilos | H147: 12 hilos | I147: 32 hilos
C148: SpeedUp Matrices 1200 x 1200 | D148: 1 | E148: =$D149/E149 -> 1.9816271 | F148: =$D149/F149 -> 3.4168589 | G148: =$D149/G149 -> 5.5089545 | H148: =$D149/H149 -> 6.4519219 | I148: =$D149/I149 -> 10.993563
C149: Promedio Matrices 1200 x 1200 | D149: ='Información completa'!M107 -> 2805986 | E149: ='Información completa'!N107 -> 1416001 | F149: ='Información completa'!O107 -> 821218 | G149: ='Información completa'!P107 -> 509350 | H149: ='Información completa'!Q107 -> 434907 | I149: ='Información completa'!R107 -> 255239
C150: # Hilos | D150: 1 hilo | E150: 2 hilos | F150: 4 hilos | G150: 8 hilos | H150: 12 hilos | I150: 32 hilos
C151: SpeedUp Matrices 2400 x 2400 | D151: 1 | E151: =$D152/E152 -> 1.8391276 | F151: =$D152/F152 -> 3.4408668 | G151: =$D152/G152 -> 5.8830262 | H151: =$D152/H152 -> 5.5842941 | I151: =$D152/I152 -> 8.5511257
C152: Promedio Matrices 2400 x 2400 | D152: ='Información completa'!U107 -> 31581026 | E152: ='Información completa'!V107 -> 17171743 | F152: ='Información completa'!W107 -> 9178218 | G152: ='Información completa'!X107 -> 5368160 | H152: ='Información completa'!Y107 -> 5655330 | I152: ='Información completa'!Z107 -> 3693201
C153: # Hilos | D153: 1 hilo | E153: 2 hilos | F153: 4 hilos | G153: 8 hilos | H153: 12 hilos | I153: 32 hilos
C154: SpeedUp Matrices 4800 x 4800 | D154: 1 | E154: =$D155/E155 -> 2.8580717 | F154: =$D155/F155 -> 5.5482939 | G154: =$D155/G155 -> 9.3377606 | H154: =$D155/H155 -> 8.6531715 | I154: =$D155/I155 -> 12.932138
C155: Promedio Matrices 4800 x 4800 | D155: ='Información completa'!AC107 -> 536677694 | E155: ='Información completa'!AD107 -> 187776148 | F155: ='Información completa'!AE107 -> 96728418 | G155: ='Información completa'!AF107 -> 57473919 | H155: ='Información completa'!AG107 -> 62020924 | I155: ='Información completa'!AH107 -> 41499532
C211: FILAS OPENMP (tiempos en microsegundos)
...

Sheet Gráficas Tiempos
D4: MATRICES 600 X 600
D5: {='Gráficas SpeedUp'!C8:I8} -> # Hilos | E5: 1 hilo | F5: 2 hilos | G5: 4 hilos | H5: 8 hilos | I5: 12 hilos | J5: 32 hilos
C6: Algoritmo | D6: Clásica Fork | E6: {='Gráficas SpeedUp'!D10:I10} -> 395790 | F6: 221549 | G6: 161865 | H6: 144469 | I6: 109948 | J6: 109489
D7: Clásica OpenMP | E7: {='Gráficas SpeedUp'!D78:I78} -> 152489 | F7: 95962 | G7: 74085 | H7: 53879 | I7: 51998 | J7: 24656
D8: Clásica POSIX | E8: {='Gráficas SpeedUp'!D146:I146} -> 392609 | F8: 239216 | G8: 178788 | H8: 151045 | I8: 128509 | J8: 72516
D9: Filas OpenMP | E9: {='Gráficas SpeedUp'!D214:I214} -> 130105 | F9: 85335 | G9: 65692 | H9: 46894 | I9: 33723 | J9: 14354
D42: MATRICES 1200 X 1200
D43: {='Gráficas SpeedUp'!C76:I76} -> # Hilos | E43: 1 hilo | F43: 2 hilos | G43: 4 hilos | H43: 8 hilos | I43: 12 hilos | J43: 32 hilos
C44: Algoritmo | D44: Clásica Fork | E44: {='Gráficas SpeedUp'!D13:I13} -> 2797186 | F44: 1417962 | G44: 831491 | H44: 539708 | I44: 439426 | J44: 274450
D45: Clásica OpenMP | E45: {='Gráficas SpeedUp'!D81:I81} -> 978412 | F45: 540877 | G45: 304147 | H45: 220224 | I45: 176600 | J45: 196862
D46: Clásica POSIX | E46: {='Gráficas SpeedUp'!D149:I149} -> 2805986 | F46: 1416001 | G46: 821218 | H46: 509350 | I46: 434907 | J46: 255239
D47: Filas OpenMP | E47: {='Gráficas SpeedUp'!D217:I217} -> 664335 | F47: 337770 | G47: 193635 | H47: 137635 | I47: 118361 | J47: 95908
D80: MATRICES 2400 X 2400
D81: {='Gráficas SpeedUp'!C144:I144} -> # Hilos | E81: 1 hilo | F81: 2 hilos | G81: 4 hilos | H81: 8 hilos | I81: 12 hilos | J81: 32 hilos
C82: Algoritmo | D82: Clásica Fork | E82: {='Gráficas SpeedUp'!D16:I16} -> 33274558 | F82: 17466949 | G82: 9105632 | H82: 5368779 | I82: 5642010 | J82: 3779028
D83: Clásica OpenMP | E83: {='Gráficas SpeedUp'!D84:I84} -> 26592717 | F83: 15768801 | G83: 7564411 | H83: 4521071 | I83: 4612473 | J83: 3729862
D84: Clásica POSIX | E84: {='Gráficas SpeedUp'!D152:I152} -> 31581026 | F84: 17171743 | G84: 9178218 | H84: 5368160 | I84: 5655330 | J84: 3693201
D85: Filas OpenMP | E85: {='Gráficas SpeedUp'!D220:I220} -> 6376706 | F85: 3359561 | G85: 1849288 | H85: 1270678 | I85: 1026778 | J85: 535656
D118: MATRICES 4800 X 4800
D119: {='Gráficas SpeedUp'!C212:I212} -> # Hilos | E119: 1 hilo | F119: 2 hilos | G119: 4 hilos | H119: 8 hilos | I119: 12 hilos | J119: 32 hilos
C120: Algoritmo | D120: Clásica Fork | E120: {='Gráficas SpeedUp'!D19:I19} -> 534112516 | F120: 188752044 | G120: 97791893 | H120: 57692937 | I120: 62382517 | J120: 42968365
D121: Clásica OpenMP | E121: {='Gráficas SpeedUp'!D87:I87} -> 721473512 | F121: 203236743 | G121: 102562613 | H121: 65972682 | I121: 62808022 | J121: 42752207
D122: Clásica POSIX | E122: {='Gráficas SpeedUp'!D155:I155} -> 536677694 | F122: 187776148 | G122: 96728418 | H122: 57473919 | I122: 62020924 | J122: 41499532
D123: Filas OpenMP | E123: {='Gráficas SpeedUp'!D223:I223} -> 51511213 | F123: 28445181 | G123: 15594130 | H123: 10536685 | I123: 9400085 | J123: 5285659
